{"uid":"4b4757e66a1912dae1a509f688f20b0f","children":[{"name":"Product defects","children":[{"name":"AssertionError: FAILED SUB-STEP: Given User is on the Home page\nSubstep info: Traceback (most recent call last):\n  File \"steps/login_steps.py\", line 17, in step_impl\n    wait_for_element_visibility(context, page_title_xpath)\n  File \"/home/runner/work/cinc_assignment/cinc_assignment/features/utils.py\", line 5, in wait_for_element_visibility\n    context.wait.until(expected_conditions.visibility_of_element_located((By.XPATH, element_xpath)))\n  File \"/home/runner/.local/lib/python3.8/site-packages/selenium/webdriver/support/wait.py\", line 90, in until\n    raise TimeoutException(message, screen, stacktrace)\nselenium.common.exceptions.TimeoutException: Message: \nStacktrace:\n#0 0x558fda8802c3 <unknown>\n#1 0x558fda68983a <unknown>\n#2 0x558fda6c2985 <unknown>\n#3 0x558fda6c2b61 <unknown>\n#4 0x558fda6fad14 <unknown>\n#5 0x558fda6e0f6d <unknown>\n#6 0x558fda6f8a50 <unknown>\n#7 0x558fda6e0d63 <unknown>\n#8 0x558fda6b57e3 <unknown>\n#9 0x558fda6b6a21 <unknown>\n#10 0x558fda8ce18e <unknown>\n#11 0x558fda8d1622 <unknown>\n#12 0x558fda8b4aae <unknown>\n#13 0x558fda8d22a3 <unknown>\n#14 0x558fda8a8ecf <unknown>\n#15 0x558fda8f2588 <unknown>\n#16 0x558fda8f2706 <unknown>\n#17 0x558fda90c8b2 <unknown>\n#18 0x7f82101ab609 <unknown>\n\n\nDuring handling of the above exception, another exception occurred:\n\nTraceback (most recent call last):\n  File \"/home/runner/.local/lib/python3.8/site-packages/behave/model.py\", line 1329, in run\n    match.run(runner.context)\n  File \"/home/runner/.local/lib/python3.8/site-packages/behave/matchers.py\", line 98, in run\n    self.func(context, *args, **kwargs)\n  File \"steps/login_steps.py\", line 26, in step_impl\n    log_out = context.driver.find_element(By.XPATH, log_out_xpath)\n  File \"/home/runner/.local/lib/python3.8/site-packages/selenium/webdriver/remote/webdriver.py\", line 856, in find_element\n    return self.execute(Command.FIND_ELEMENT, {\n  File \"/home/runner/.local/lib/python3.8/site-packages/selenium/webdriver/remote/webdriver.py\", line 429, in execute\n    self.error_handler.check_response(response)\n  File \"/home/runner/.local/lib/python3.8/site-packages/selenium/webdriver/remote/errorhandler.py\", line 243, in check_response\n    raise exception_class(message, screen, stacktrace)\nselenium.common.exceptions.NoSuchElementException: Message: no such element: Unable to locate element: {\"method\":\"xpath\",\"selector\":\"/html/body/div/div[1]/div/nav/ul/li[4]/div/ul/li[6]/a\"}\n  (Session info: headless chrome=106.0.5249.119)\nStacktrace:\n#0 0x558fda8802c3 <unknown>\n#1 0x558fda68983a <unknown>\n#2 0x558fda6c2985 <unknown>\n#3 0x558fda6c2b61 <unknown>\n#4 0x558fda6fad14 <unknown>\n#5 0x558fda6e0f6d <unknown>\n#6 0x558fda6f8a50 <unknown>\n#7 0x558fda6e0d63 <unknown>\n#8 0x558fda6b57e3 <unknown>\n#9 0x558fda6b6a21 <unknown>\n#10 0x558fda8ce18e <unknown>\n#11 0x558fda8d1622 <unknown>\n#12 0x558fda8b4aae <unknown>\n#13 0x558fda8d22a3 <unknown>\n#14 0x558fda8a8ecf <unknown>\n#15 0x558fda8f2588 <unknown>\n#16 0x558fda8f2706 <unknown>\n#17 0x558fda90c8b2 <unknown>\n#18 0x7f82101ab609 <unknown>\n\n\nTraceback (of failed substep):\n  File \"/home/runner/.local/lib/python3.8/site-packages/behave/model.py\", line 1329, in run\n    match.run(runner.context)\n  File \"/home/runner/.local/lib/python3.8/site-packages/behave/matchers.py\", line 98, in run\n    self.func(context, *args, **kwargs)\n  File \"steps/login_steps.py\", line 26, in step_impl\n    log_out = context.driver.find_element(By.XPATH, log_out_xpath)\n  File \"/home/runner/.local/lib/python3.8/site-packages/selenium/webdriver/remote/webdriver.py\", line 856, in find_element\n    return self.execute(Command.FIND_ELEMENT, {\n  File \"/home/runner/.local/lib/python3.8/site-packages/selenium/webdriver/remote/webdriver.py\", line 429, in execute\n    self.error_handler.check_response(response)\n  File \"/home/runner/.local/lib/python3.8/site-packages/selenium/webdriver/remote/errorhandler.py\", line 243, in check_response\n    raise exception_class(message, screen, stacktrace)\n\n","children":[{"name":"Add a Recipe to a Collection -- @1.1 ","uid":"660cfe7574c2072c","parentUid":"698bae200f7e1f45a866271b28afa227","status":"failed","time":{"start":1667421673528,"stop":1667421683918,"duration":10390},"flaky":true,"newFailed":true,"newPassed":false,"newBroken":false,"retriesCount":0,"retriesStatusChange":false,"parameters":["uhqom-duqmum-tepXe7","Test Collection","technical_assignment"]},{"name":"User can add a Collection with the same name as a deleted Collection -- @1.1 ","uid":"f65160d74254cfe","parentUid":"698bae200f7e1f45a866271b28afa227","status":"failed","time":{"start":1667421683918,"stop":1667421694281,"duration":10363},"flaky":false,"newFailed":false,"newPassed":false,"newBroken":false,"retriesCount":0,"retriesStatusChange":false,"parameters":["You already have a collection with that title.","uhqom-duqmum-tepXe7","Test Collection","technical_assignment"]}],"uid":"698bae200f7e1f45a866271b28afa227"}],"uid":"8fb3a91ba5aaf9de24cc8a92edc82b5d"}],"name":"categories"}