{"uid":"4b4757e66a1912dae1a509f688f20b0f","children":[{"name":"Product defects","children":[{"name":"AssertionError: FAILED SUB-STEP: Given User is on the Home page\nSubstep info: Traceback (most recent call last):\n  File \"steps/login_steps.py\", line 17, in step_impl\n    wait_for_element_visibility(context, page_title_xpath)\n  File \"/home/runner/work/cinc_assignment/cinc_assignment/features/utils.py\", line 5, in wait_for_element_visibility\n    context.wait.until(expected_conditions.visibility_of_element_located((By.XPATH, element_xpath)))\n  File \"/home/runner/.local/lib/python3.8/site-packages/selenium/webdriver/support/wait.py\", line 90, in until\n    raise TimeoutException(message, screen, stacktrace)\nselenium.common.exceptions.TimeoutException: Message: \nStacktrace:\n#0 0x55af806102c3 <unknown>\n#1 0x55af8041983a <unknown>\n#2 0x55af80452985 <unknown>\n#3 0x55af80452b61 <unknown>\n#4 0x55af8048ad14 <unknown>\n#5 0x55af80470f6d <unknown>\n#6 0x55af80488a50 <unknown>\n#7 0x55af80470d63 <unknown>\n#8 0x55af804457e3 <unknown>\n#9 0x55af80446a21 <unknown>\n#10 0x55af8065e18e <unknown>\n#11 0x55af80661622 <unknown>\n#12 0x55af80644aae <unknown>\n#13 0x55af806622a3 <unknown>\n#14 0x55af80638ecf <unknown>\n#15 0x55af80682588 <unknown>\n#16 0x55af80682706 <unknown>\n#17 0x55af8069c8b2 <unknown>\n#18 0x7fcabf406609 <unknown>\n\n\nDuring handling of the above exception, another exception occurred:\n\nTraceback (most recent call last):\n  File \"/home/runner/.local/lib/python3.8/site-packages/behave/model.py\", line 1329, in run\n    match.run(runner.context)\n  File \"/home/runner/.local/lib/python3.8/site-packages/behave/matchers.py\", line 98, in run\n    self.func(context, *args, **kwargs)\n  File \"steps/login_steps.py\", line 26, in step_impl\n    log_out = context.driver.find_element(By.XPATH, log_out_xpath)\n  File \"/home/runner/.local/lib/python3.8/site-packages/selenium/webdriver/remote/webdriver.py\", line 856, in find_element\n    return self.execute(Command.FIND_ELEMENT, {\n  File \"/home/runner/.local/lib/python3.8/site-packages/selenium/webdriver/remote/webdriver.py\", line 429, in execute\n    self.error_handler.check_response(response)\n  File \"/home/runner/.local/lib/python3.8/site-packages/selenium/webdriver/remote/errorhandler.py\", line 243, in check_response\n    raise exception_class(message, screen, stacktrace)\nselenium.common.exceptions.NoSuchElementException: Message: no such element: Unable to locate element: {\"method\":\"xpath\",\"selector\":\"/html/body/div/div[1]/div/nav/ul/li[4]/div/ul/li[6]/a\"}\n  (Session info: headless chrome=106.0.5249.119)\nStacktrace:\n#0 0x55af806102c3 <unknown>\n#1 0x55af8041983a <unknown>\n#2 0x55af80452985 <unknown>\n#3 0x55af80452b61 <unknown>\n#4 0x55af8048ad14 <unknown>\n#5 0x55af80470f6d <unknown>\n#6 0x55af80488a50 <unknown>\n#7 0x55af80470d63 <unknown>\n#8 0x55af804457e3 <unknown>\n#9 0x55af80446a21 <unknown>\n#10 0x55af8065e18e <unknown>\n#11 0x55af80661622 <unknown>\n#12 0x55af80644aae <unknown>\n#13 0x55af806622a3 <unknown>\n#14 0x55af80638ecf <unknown>\n#15 0x55af80682588 <unknown>\n#16 0x55af80682706 <unknown>\n#17 0x55af8069c8b2 <unknown>\n#18 0x7fcabf406609 <unknown>\n\n\nTraceback (of failed substep):\n  File \"/home/runner/.local/lib/python3.8/site-packages/behave/model.py\", line 1329, in run\n    match.run(runner.context)\n  File \"/home/runner/.local/lib/python3.8/site-packages/behave/matchers.py\", line 98, in run\n    self.func(context, *args, **kwargs)\n  File \"steps/login_steps.py\", line 26, in step_impl\n    log_out = context.driver.find_element(By.XPATH, log_out_xpath)\n  File \"/home/runner/.local/lib/python3.8/site-packages/selenium/webdriver/remote/webdriver.py\", line 856, in find_element\n    return self.execute(Command.FIND_ELEMENT, {\n  File \"/home/runner/.local/lib/python3.8/site-packages/selenium/webdriver/remote/webdriver.py\", line 429, in execute\n    self.error_handler.check_response(response)\n  File \"/home/runner/.local/lib/python3.8/site-packages/selenium/webdriver/remote/errorhandler.py\", line 243, in check_response\n    raise exception_class(message, screen, stacktrace)\n\n","children":[{"name":"Add a Recipe to a Collection -- @1.1 ","uid":"694144784d463598","parentUid":"a3741601ff268916b00e123e4e5b4f88","status":"failed","time":{"start":1667421134800,"stop":1667421145197,"duration":10397},"flaky":false,"newFailed":true,"newPassed":false,"newBroken":false,"retriesCount":0,"retriesStatusChange":false,"parameters":["uhqom-duqmum-tepXe7","Test Collection","technical_assignment"]},{"name":"Recipe adjustment -- @1.1 ","uid":"ff19ead8aeb7d483","parentUid":"a3741601ff268916b00e123e4e5b4f88","status":"failed","time":{"start":1667421170236,"stop":1667421180586,"duration":10350},"flaky":true,"newFailed":true,"newPassed":false,"newBroken":false,"retriesCount":0,"retriesStatusChange":false,"parameters":["uhqom-duqmum-tepXe7","technical_assignment"]}],"uid":"a3741601ff268916b00e123e4e5b4f88"},{"name":"AssertionError\n","children":[{"name":"User can add a Collection with the same name as a deleted Collection -- @1.1 ","uid":"789b8b4645faf5ff","parentUid":"a730cf0b0a23aabea6d11aa0391c8a76","status":"failed","time":{"start":1667421145198,"stop":1667421158656,"duration":13458},"flaky":false,"newFailed":false,"newPassed":false,"newBroken":false,"retriesCount":0,"retriesStatusChange":false,"parameters":["You already have a collection with that title.","uhqom-duqmum-tepXe7","Test Collection","technical_assignment"]}],"uid":"a730cf0b0a23aabea6d11aa0391c8a76"}],"uid":"8fb3a91ba5aaf9de24cc8a92edc82b5d"}],"name":"categories"}