{"uid":"4b4757e66a1912dae1a509f688f20b0f","children":[{"name":"Product defects","children":[{"name":"AssertionError: FAILED SUB-STEP: Given User is on the Home page\nSubstep info: Traceback (most recent call last):\n  File \"steps/login_steps.py\", line 18, in step_impl\n    wait_for_element_visibility(context, page_title_xpath)\n  File \"/home/runner/work/cinc_assignment/cinc_assignment/features/utils.py\", line 5, in wait_for_element_visibility\n    context.wait.until(expected_conditions.visibility_of_element_located((By.XPATH, element_xpath)))\n  File \"/home/runner/.local/lib/python3.8/site-packages/selenium/webdriver/support/wait.py\", line 90, in until\n    raise TimeoutException(message, screen, stacktrace)\nselenium.common.exceptions.TimeoutException: Message: \nStacktrace:\n#0 0x5582c31432c3 <unknown>\n#1 0x5582c2f4c83a <unknown>\n#2 0x5582c2f85985 <unknown>\n#3 0x5582c2f85b61 <unknown>\n#4 0x5582c2fbdd14 <unknown>\n#5 0x5582c2fa3f6d <unknown>\n#6 0x5582c2fbba50 <unknown>\n#7 0x5582c2fa3d63 <unknown>\n#8 0x5582c2f787e3 <unknown>\n#9 0x5582c2f79a21 <unknown>\n#10 0x5582c319118e <unknown>\n#11 0x5582c3194622 <unknown>\n#12 0x5582c3177aae <unknown>\n#13 0x5582c31952a3 <unknown>\n#14 0x5582c316becf <unknown>\n#15 0x5582c31b5588 <unknown>\n#16 0x5582c31b5706 <unknown>\n#17 0x5582c31cf8b2 <unknown>\n#18 0x7fd57c78c609 <unknown>\n\n\nDuring handling of the above exception, another exception occurred:\n\nTraceback (most recent call last):\n  File \"/home/runner/.local/lib/python3.8/site-packages/behave/model.py\", line 1329, in run\n    match.run(runner.context)\n  File \"/home/runner/.local/lib/python3.8/site-packages/behave/matchers.py\", line 98, in run\n    self.func(context, *args, **kwargs)\n  File \"steps/login_steps.py\", line 27, in step_impl\n    log_out = context.driver.find_element(By.XPATH, log_out_xpath)\n  File \"/home/runner/.local/lib/python3.8/site-packages/selenium/webdriver/remote/webdriver.py\", line 856, in find_element\n    return self.execute(Command.FIND_ELEMENT, {\n  File \"/home/runner/.local/lib/python3.8/site-packages/selenium/webdriver/remote/webdriver.py\", line 429, in execute\n    self.error_handler.check_response(response)\n  File \"/home/runner/.local/lib/python3.8/site-packages/selenium/webdriver/remote/errorhandler.py\", line 243, in check_response\n    raise exception_class(message, screen, stacktrace)\nselenium.common.exceptions.NoSuchElementException: Message: no such element: Unable to locate element: {\"method\":\"xpath\",\"selector\":\"/html/body/div/div[1]/div/nav/ul/li[4]/div/ul/li[6]/a\"}\n  (Session info: headless chrome=106.0.5249.119)\nStacktrace:\n#0 0x5582c31432c3 <unknown>\n#1 0x5582c2f4c83a <unknown>\n#2 0x5582c2f85985 <unknown>\n#3 0x5582c2f85b61 <unknown>\n#4 0x5582c2fbdd14 <unknown>\n#5 0x5582c2fa3f6d <unknown>\n#6 0x5582c2fbba50 <unknown>\n#7 0x5582c2fa3d63 <unknown>\n#8 0x5582c2f787e3 <unknown>\n#9 0x5582c2f79a21 <unknown>\n#10 0x5582c319118e <unknown>\n#11 0x5582c3194622 <unknown>\n#12 0x5582c3177aae <unknown>\n#13 0x5582c31952a3 <unknown>\n#14 0x5582c316becf <unknown>\n#15 0x5582c31b5588 <unknown>\n#16 0x5582c31b5706 <unknown>\n#17 0x5582c31cf8b2 <unknown>\n#18 0x7fd57c78c609 <unknown>\n\n\nTraceback (of failed substep):\n  File \"/home/runner/.local/lib/python3.8/site-packages/behave/model.py\", line 1329, in run\n    match.run(runner.context)\n  File \"/home/runner/.local/lib/python3.8/site-packages/behave/matchers.py\", line 98, in run\n    self.func(context, *args, **kwargs)\n  File \"steps/login_steps.py\", line 27, in step_impl\n    log_out = context.driver.find_element(By.XPATH, log_out_xpath)\n  File \"/home/runner/.local/lib/python3.8/site-packages/selenium/webdriver/remote/webdriver.py\", line 856, in find_element\n    return self.execute(Command.FIND_ELEMENT, {\n  File \"/home/runner/.local/lib/python3.8/site-packages/selenium/webdriver/remote/webdriver.py\", line 429, in execute\n    self.error_handler.check_response(response)\n  File \"/home/runner/.local/lib/python3.8/site-packages/selenium/webdriver/remote/errorhandler.py\", line 243, in check_response\n    raise exception_class(message, screen, stacktrace)\n\n","children":[{"name":"Add a Recipe to a Collection -- @1.1 ","uid":"bb815d82163df7a","parentUid":"2f0c4be12925b01723b788d6537db4c3","status":"failed","time":{"start":1667414585984,"stop":1667414596389,"duration":10405},"flaky":true,"newFailed":false,"newPassed":false,"newBroken":false,"retriesCount":0,"retriesStatusChange":false,"parameters":["uhqom-duqmum-tepXe7","Test Collection","technical_assignment"]}],"uid":"2f0c4be12925b01723b788d6537db4c3"},{"name":"AssertionError\n","children":[{"name":"User can add a Collection with the same name as a deleted Collection -- @1.1 ","uid":"7b881886dc96b54d","parentUid":"a730cf0b0a23aabea6d11aa0391c8a76","status":"failed","time":{"start":1667414596390,"stop":1667414608984,"duration":12594},"flaky":false,"newFailed":false,"newPassed":false,"newBroken":false,"retriesCount":0,"retriesStatusChange":false,"parameters":["You already have a collection with that title.","uhqom-duqmum-tepXe7","Test Collection","technical_assignment"]}],"uid":"a730cf0b0a23aabea6d11aa0391c8a76"}],"uid":"8fb3a91ba5aaf9de24cc8a92edc82b5d"}],"name":"categories"}