{"uid":"f65160d74254cfe","name":"User can add a Collection with the same name as a deleted Collection -- @1.1 ","fullName":"Collections: User can add a Collection with the same name as a deleted Collection","historyId":"a34d535ff7756f44d3753d91bfe6b623","time":{"start":1667421683918,"stop":1667421694281,"duration":10363},"status":"failed","statusMessage":"AssertionError: FAILED SUB-STEP: Given User is on the Home page\nSubstep info: Traceback (most recent call last):\n  File \"steps/login_steps.py\", line 17, in step_impl\n    wait_for_element_visibility(context, page_title_xpath)\n  File \"/home/runner/work/cinc_assignment/cinc_assignment/features/utils.py\", line 5, in wait_for_element_visibility\n    context.wait.until(expected_conditions.visibility_of_element_located((By.XPATH, element_xpath)))\n  File \"/home/runner/.local/lib/python3.8/site-packages/selenium/webdriver/support/wait.py\", line 90, in until\n    raise TimeoutException(message, screen, stacktrace)\nselenium.common.exceptions.TimeoutException: Message: \nStacktrace:\n#0 0x558fda8802c3 <unknown>\n#1 0x558fda68983a <unknown>\n#2 0x558fda6c2985 <unknown>\n#3 0x558fda6c2b61 <unknown>\n#4 0x558fda6fad14 <unknown>\n#5 0x558fda6e0f6d <unknown>\n#6 0x558fda6f8a50 <unknown>\n#7 0x558fda6e0d63 <unknown>\n#8 0x558fda6b57e3 <unknown>\n#9 0x558fda6b6a21 <unknown>\n#10 0x558fda8ce18e <unknown>\n#11 0x558fda8d1622 <unknown>\n#12 0x558fda8b4aae <unknown>\n#13 0x558fda8d22a3 <unknown>\n#14 0x558fda8a8ecf <unknown>\n#15 0x558fda8f2588 <unknown>\n#16 0x558fda8f2706 <unknown>\n#17 0x558fda90c8b2 <unknown>\n#18 0x7f82101ab609 <unknown>\n\n\nDuring handling of the above exception, another exception occurred:\n\nTraceback (most recent call last):\n  File \"/home/runner/.local/lib/python3.8/site-packages/behave/model.py\", line 1329, in run\n    match.run(runner.context)\n  File \"/home/runner/.local/lib/python3.8/site-packages/behave/matchers.py\", line 98, in run\n    self.func(context, *args, **kwargs)\n  File \"steps/login_steps.py\", line 26, in step_impl\n    log_out = context.driver.find_element(By.XPATH, log_out_xpath)\n  File \"/home/runner/.local/lib/python3.8/site-packages/selenium/webdriver/remote/webdriver.py\", line 856, in find_element\n    return self.execute(Command.FIND_ELEMENT, {\n  File \"/home/runner/.local/lib/python3.8/site-packages/selenium/webdriver/remote/webdriver.py\", line 429, in execute\n    self.error_handler.check_response(response)\n  File \"/home/runner/.local/lib/python3.8/site-packages/selenium/webdriver/remote/errorhandler.py\", line 243, in check_response\n    raise exception_class(message, screen, stacktrace)\nselenium.common.exceptions.NoSuchElementException: Message: no such element: Unable to locate element: {\"method\":\"xpath\",\"selector\":\"/html/body/div/div[1]/div/nav/ul/li[4]/div/ul/li[6]/a\"}\n  (Session info: headless chrome=106.0.5249.119)\nStacktrace:\n#0 0x558fda8802c3 <unknown>\n#1 0x558fda68983a <unknown>\n#2 0x558fda6c2985 <unknown>\n#3 0x558fda6c2b61 <unknown>\n#4 0x558fda6fad14 <unknown>\n#5 0x558fda6e0f6d <unknown>\n#6 0x558fda6f8a50 <unknown>\n#7 0x558fda6e0d63 <unknown>\n#8 0x558fda6b57e3 <unknown>\n#9 0x558fda6b6a21 <unknown>\n#10 0x558fda8ce18e <unknown>\n#11 0x558fda8d1622 <unknown>\n#12 0x558fda8b4aae <unknown>\n#13 0x558fda8d22a3 <unknown>\n#14 0x558fda8a8ecf <unknown>\n#15 0x558fda8f2588 <unknown>\n#16 0x558fda8f2706 <unknown>\n#17 0x558fda90c8b2 <unknown>\n#18 0x7f82101ab609 <unknown>\n\n\nTraceback (of failed substep):\n  File \"/home/runner/.local/lib/python3.8/site-packages/behave/model.py\", line 1329, in run\n    match.run(runner.context)\n  File \"/home/runner/.local/lib/python3.8/site-packages/behave/matchers.py\", line 98, in run\n    self.func(context, *args, **kwargs)\n  File \"steps/login_steps.py\", line 26, in step_impl\n    log_out = context.driver.find_element(By.XPATH, log_out_xpath)\n  File \"/home/runner/.local/lib/python3.8/site-packages/selenium/webdriver/remote/webdriver.py\", line 856, in find_element\n    return self.execute(Command.FIND_ELEMENT, {\n  File \"/home/runner/.local/lib/python3.8/site-packages/selenium/webdriver/remote/webdriver.py\", line 429, in execute\n    self.error_handler.check_response(response)\n  File \"/home/runner/.local/lib/python3.8/site-packages/selenium/webdriver/remote/errorhandler.py\", line 243, in check_response\n    raise exception_class(message, screen, stacktrace)\n\n","statusTrace":"  File \"/home/runner/.local/lib/python3.8/site-packages/behave/model.py\", line 1329, in run\n    match.run(runner.context)\n  File \"/home/runner/.local/lib/python3.8/site-packages/behave/matchers.py\", line 98, in run\n    self.func(context, *args, **kwargs)\n  File \"steps/collection_steps.py\", line 19, in step_impl\n    context.execute_steps(f\"\"\"\n  File \"/home/runner/.local/lib/python3.8/site-packages/behave/runner.py\", line 404, in execute_steps\n    assert False, message\n","flaky":false,"newFailed":false,"newBroken":false,"newPassed":false,"retriesCount":0,"retriesStatusChange":false,"beforeStages":[],"testStage":{"status":"failed","statusMessage":"AssertionError: FAILED SUB-STEP: Given User is on the Home page\nSubstep info: Traceback (most recent call last):\n  File \"steps/login_steps.py\", line 17, in step_impl\n    wait_for_element_visibility(context, page_title_xpath)\n  File \"/home/runner/work/cinc_assignment/cinc_assignment/features/utils.py\", line 5, in wait_for_element_visibility\n    context.wait.until(expected_conditions.visibility_of_element_located((By.XPATH, element_xpath)))\n  File \"/home/runner/.local/lib/python3.8/site-packages/selenium/webdriver/support/wait.py\", line 90, in until\n    raise TimeoutException(message, screen, stacktrace)\nselenium.common.exceptions.TimeoutException: Message: \nStacktrace:\n#0 0x558fda8802c3 <unknown>\n#1 0x558fda68983a <unknown>\n#2 0x558fda6c2985 <unknown>\n#3 0x558fda6c2b61 <unknown>\n#4 0x558fda6fad14 <unknown>\n#5 0x558fda6e0f6d <unknown>\n#6 0x558fda6f8a50 <unknown>\n#7 0x558fda6e0d63 <unknown>\n#8 0x558fda6b57e3 <unknown>\n#9 0x558fda6b6a21 <unknown>\n#10 0x558fda8ce18e <unknown>\n#11 0x558fda8d1622 <unknown>\n#12 0x558fda8b4aae <unknown>\n#13 0x558fda8d22a3 <unknown>\n#14 0x558fda8a8ecf <unknown>\n#15 0x558fda8f2588 <unknown>\n#16 0x558fda8f2706 <unknown>\n#17 0x558fda90c8b2 <unknown>\n#18 0x7f82101ab609 <unknown>\n\n\nDuring handling of the above exception, another exception occurred:\n\nTraceback (most recent call last):\n  File \"/home/runner/.local/lib/python3.8/site-packages/behave/model.py\", line 1329, in run\n    match.run(runner.context)\n  File \"/home/runner/.local/lib/python3.8/site-packages/behave/matchers.py\", line 98, in run\n    self.func(context, *args, **kwargs)\n  File \"steps/login_steps.py\", line 26, in step_impl\n    log_out = context.driver.find_element(By.XPATH, log_out_xpath)\n  File \"/home/runner/.local/lib/python3.8/site-packages/selenium/webdriver/remote/webdriver.py\", line 856, in find_element\n    return self.execute(Command.FIND_ELEMENT, {\n  File \"/home/runner/.local/lib/python3.8/site-packages/selenium/webdriver/remote/webdriver.py\", line 429, in execute\n    self.error_handler.check_response(response)\n  File \"/home/runner/.local/lib/python3.8/site-packages/selenium/webdriver/remote/errorhandler.py\", line 243, in check_response\n    raise exception_class(message, screen, stacktrace)\nselenium.common.exceptions.NoSuchElementException: Message: no such element: Unable to locate element: {\"method\":\"xpath\",\"selector\":\"/html/body/div/div[1]/div/nav/ul/li[4]/div/ul/li[6]/a\"}\n  (Session info: headless chrome=106.0.5249.119)\nStacktrace:\n#0 0x558fda8802c3 <unknown>\n#1 0x558fda68983a <unknown>\n#2 0x558fda6c2985 <unknown>\n#3 0x558fda6c2b61 <unknown>\n#4 0x558fda6fad14 <unknown>\n#5 0x558fda6e0f6d <unknown>\n#6 0x558fda6f8a50 <unknown>\n#7 0x558fda6e0d63 <unknown>\n#8 0x558fda6b57e3 <unknown>\n#9 0x558fda6b6a21 <unknown>\n#10 0x558fda8ce18e <unknown>\n#11 0x558fda8d1622 <unknown>\n#12 0x558fda8b4aae <unknown>\n#13 0x558fda8d22a3 <unknown>\n#14 0x558fda8a8ecf <unknown>\n#15 0x558fda8f2588 <unknown>\n#16 0x558fda8f2706 <unknown>\n#17 0x558fda90c8b2 <unknown>\n#18 0x7f82101ab609 <unknown>\n\n\nTraceback (of failed substep):\n  File \"/home/runner/.local/lib/python3.8/site-packages/behave/model.py\", line 1329, in run\n    match.run(runner.context)\n  File \"/home/runner/.local/lib/python3.8/site-packages/behave/matchers.py\", line 98, in run\n    self.func(context, *args, **kwargs)\n  File \"steps/login_steps.py\", line 26, in step_impl\n    log_out = context.driver.find_element(By.XPATH, log_out_xpath)\n  File \"/home/runner/.local/lib/python3.8/site-packages/selenium/webdriver/remote/webdriver.py\", line 856, in find_element\n    return self.execute(Command.FIND_ELEMENT, {\n  File \"/home/runner/.local/lib/python3.8/site-packages/selenium/webdriver/remote/webdriver.py\", line 429, in execute\n    self.error_handler.check_response(response)\n  File \"/home/runner/.local/lib/python3.8/site-packages/selenium/webdriver/remote/errorhandler.py\", line 243, in check_response\n    raise exception_class(message, screen, stacktrace)\n\n","statusTrace":"  File \"/home/runner/.local/lib/python3.8/site-packages/behave/model.py\", line 1329, in run\n    match.run(runner.context)\n  File \"/home/runner/.local/lib/python3.8/site-packages/behave/matchers.py\", line 98, in run\n    self.func(context, *args, **kwargs)\n  File \"steps/collection_steps.py\", line 19, in step_impl\n    context.execute_steps(f\"\"\"\n  File \"/home/runner/.local/lib/python3.8/site-packages/behave/runner.py\", line 404, in execute_steps\n    assert False, message\n","steps":[{"name":"Given User is logged in as username: technical_assignment, password: uhqom-duqmum-tepXe7","time":{"start":1667421683920,"stop":1667421694280,"duration":10360},"status":"failed","statusMessage":"AssertionError: FAILED SUB-STEP: Given User is on the Home page\nSubstep info: Traceback (most recent call last):\n  File \"steps/login_steps.py\", line 17, in step_impl\n    wait_for_element_visibility(context, page_title_xpath)\n  File \"/home/runner/work/cinc_assignment/cinc_assignment/features/utils.py\", line 5, in wait_for_element_visibility\n    context.wait.until(expected_conditions.visibility_of_element_located((By.XPATH, element_xpath)))\n  File \"/home/runner/.local/lib/python3.8/site-packages/selenium/webdriver/support/wait.py\", line 90, in until\n    raise TimeoutException(message, screen, stacktrace)\nselenium.common.exceptions.TimeoutException: Message: \nStacktrace:\n#0 0x558fda8802c3 <unknown>\n#1 0x558fda68983a <unknown>\n#2 0x558fda6c2985 <unknown>\n#3 0x558fda6c2b61 <unknown>\n#4 0x558fda6fad14 <unknown>\n#5 0x558fda6e0f6d <unknown>\n#6 0x558fda6f8a50 <unknown>\n#7 0x558fda6e0d63 <unknown>\n#8 0x558fda6b57e3 <unknown>\n#9 0x558fda6b6a21 <unknown>\n#10 0x558fda8ce18e <unknown>\n#11 0x558fda8d1622 <unknown>\n#12 0x558fda8b4aae <unknown>\n#13 0x558fda8d22a3 <unknown>\n#14 0x558fda8a8ecf <unknown>\n#15 0x558fda8f2588 <unknown>\n#16 0x558fda8f2706 <unknown>\n#17 0x558fda90c8b2 <unknown>\n#18 0x7f82101ab609 <unknown>\n\n\nDuring handling of the above exception, another exception occurred:\n\nTraceback (most recent call last):\n  File \"/home/runner/.local/lib/python3.8/site-packages/behave/model.py\", line 1329, in run\n    match.run(runner.context)\n  File \"/home/runner/.local/lib/python3.8/site-packages/behave/matchers.py\", line 98, in run\n    self.func(context, *args, **kwargs)\n  File \"steps/login_steps.py\", line 26, in step_impl\n    log_out = context.driver.find_element(By.XPATH, log_out_xpath)\n  File \"/home/runner/.local/lib/python3.8/site-packages/selenium/webdriver/remote/webdriver.py\", line 856, in find_element\n    return self.execute(Command.FIND_ELEMENT, {\n  File \"/home/runner/.local/lib/python3.8/site-packages/selenium/webdriver/remote/webdriver.py\", line 429, in execute\n    self.error_handler.check_response(response)\n  File \"/home/runner/.local/lib/python3.8/site-packages/selenium/webdriver/remote/errorhandler.py\", line 243, in check_response\n    raise exception_class(message, screen, stacktrace)\nselenium.common.exceptions.NoSuchElementException: Message: no such element: Unable to locate element: {\"method\":\"xpath\",\"selector\":\"/html/body/div/div[1]/div/nav/ul/li[4]/div/ul/li[6]/a\"}\n  (Session info: headless chrome=106.0.5249.119)\nStacktrace:\n#0 0x558fda8802c3 <unknown>\n#1 0x558fda68983a <unknown>\n#2 0x558fda6c2985 <unknown>\n#3 0x558fda6c2b61 <unknown>\n#4 0x558fda6fad14 <unknown>\n#5 0x558fda6e0f6d <unknown>\n#6 0x558fda6f8a50 <unknown>\n#7 0x558fda6e0d63 <unknown>\n#8 0x558fda6b57e3 <unknown>\n#9 0x558fda6b6a21 <unknown>\n#10 0x558fda8ce18e <unknown>\n#11 0x558fda8d1622 <unknown>\n#12 0x558fda8b4aae <unknown>\n#13 0x558fda8d22a3 <unknown>\n#14 0x558fda8a8ecf <unknown>\n#15 0x558fda8f2588 <unknown>\n#16 0x558fda8f2706 <unknown>\n#17 0x558fda90c8b2 <unknown>\n#18 0x7f82101ab609 <unknown>\n\n\nTraceback (of failed substep):\n  File \"/home/runner/.local/lib/python3.8/site-packages/behave/model.py\", line 1329, in run\n    match.run(runner.context)\n  File \"/home/runner/.local/lib/python3.8/site-packages/behave/matchers.py\", line 98, in run\n    self.func(context, *args, **kwargs)\n  File \"steps/login_steps.py\", line 26, in step_impl\n    log_out = context.driver.find_element(By.XPATH, log_out_xpath)\n  File \"/home/runner/.local/lib/python3.8/site-packages/selenium/webdriver/remote/webdriver.py\", line 856, in find_element\n    return self.execute(Command.FIND_ELEMENT, {\n  File \"/home/runner/.local/lib/python3.8/site-packages/selenium/webdriver/remote/webdriver.py\", line 429, in execute\n    self.error_handler.check_response(response)\n  File \"/home/runner/.local/lib/python3.8/site-packages/selenium/webdriver/remote/errorhandler.py\", line 243, in check_response\n    raise exception_class(message, screen, stacktrace)\n\n","statusTrace":"  File \"/home/runner/.local/lib/python3.8/site-packages/behave/model.py\", line 1329, in run\n    match.run(runner.context)\n  File \"/home/runner/.local/lib/python3.8/site-packages/behave/matchers.py\", line 98, in run\n    self.func(context, *args, **kwargs)\n  File \"steps/collection_steps.py\", line 19, in step_impl\n    context.execute_steps(f\"\"\"\n  File \"/home/runner/.local/lib/python3.8/site-packages/behave/runner.py\", line 404, in execute_steps\n    assert False, message\n","steps":[],"attachments":[],"parameters":[],"stepsCount":0,"attachmentsCount":0,"shouldDisplayMessage":true,"hasContent":true},{"name":"When User adds a Collection with title: Test Collection","time":{"start":1667421694281,"stop":1667421694281,"duration":0},"status":"skipped","steps":[],"attachments":[],"parameters":[],"stepsCount":0,"attachmentsCount":0,"shouldDisplayMessage":false,"hasContent":false},{"name":"Then Error: You already have a collection with that title., does not appear","time":{"start":1667421694281,"stop":1667421694281,"duration":0},"status":"skipped","steps":[],"attachments":[],"parameters":[],"stepsCount":0,"attachmentsCount":0,"shouldDisplayMessage":false,"hasContent":false}],"attachments":[],"parameters":[],"stepsCount":3,"attachmentsCount":0,"shouldDisplayMessage":false,"hasContent":true},"afterStages":[],"labels":[{"name":"severity","value":"normal"},{"name":"feature","value":"Collections"},{"name":"framework","value":"behave"},{"name":"language","value":"cpython3"},{"name":"resultFormat","value":"allure2"}],"parameters":[{"name":"error_message","value":"You already have a collection with that title."},{"name":"password","value":"uhqom-duqmum-tepXe7"},{"name":"title","value":"Test Collection"},{"name":"username","value":"technical_assignment"}],"links":[],"hidden":false,"retry":false,"extra":{"severity":"normal","retries":[],"categories":[{"name":"Product defects","matchedStatuses":[],"flaky":false}],"history":{"statistic":{"failed":23,"broken":0,"skipped":0,"passed":0,"unknown":0,"total":23},"items":[{"uid":"5b331b2425eba50d","reportUrl":"https://timjden.github.io/cinc_assignment/41//#testresult/5b331b2425eba50d","status":"failed","statusDetails":"AssertionError\n","time":{"start":1667421344238,"stop":1667421357430,"duration":13192}},{"uid":"ac60ba047854cc1d","reportUrl":"https://timjden.github.io/cinc_assignment/40//#testresult/ac60ba047854cc1d","status":"failed","statusDetails":"AssertionError\n","time":{"start":1667421290961,"stop":1667421304086,"duration":13125}},{"uid":"789b8b4645faf5ff","reportUrl":"https://timjden.github.io/cinc_assignment/39//#testresult/789b8b4645faf5ff","status":"failed","statusDetails":"AssertionError\n","time":{"start":1667421145198,"stop":1667421158656,"duration":13458}},{"uid":"d5734b4d03c9706a","reportUrl":"https://timjden.github.io/cinc_assignment/38//#testresult/d5734b4d03c9706a","status":"failed","statusDetails":"AssertionError\n","time":{"start":1667421061869,"stop":1667421074622,"duration":12753}},{"uid":"8f1d46ae89e855df","reportUrl":"https://timjden.github.io/cinc_assignment/37//#testresult/8f1d46ae89e855df","status":"failed","statusDetails":"AssertionError\n","time":{"start":1667420804922,"stop":1667420817707,"duration":12785}},{"uid":"13ed746cd1b8a8be","reportUrl":"https://timjden.github.io/cinc_assignment/37//#testresult/13ed746cd1b8a8be","status":"failed","statusDetails":"AssertionError\n","time":{"start":1667420463646,"stop":1667420477424,"duration":13778}},{"uid":"232389680310f936","reportUrl":"https://timjden.github.io/cinc_assignment/36//#testresult/232389680310f936","status":"failed","statusDetails":"AssertionError\n","time":{"start":1667420228027,"stop":1667420240963,"duration":12936}},{"uid":"ecc139ce33d4e532","reportUrl":"https://timjden.github.io/cinc_assignment/36//#testresult/ecc139ce33d4e532","status":"failed","statusDetails":"AssertionError: FAILED SUB-STEP: Given User is on the Home page\nSubstep info: Traceback (most recent call last):\n  File \"steps/login_steps.py\", line 17, in step_impl\n    wait_for_element_visibility(context, page_title_xpath)\n  File \"/home/runner/work/cinc_assignment/cinc_assignment/features/utils.py\", line 5, in wait_for_element_visibility\n    context.wait.until(expected_conditions.visibility_of_element_located((By.XPATH, element_xpath)))\n  File \"/home/runner/.local/lib/python3.8/site-packages/selenium/webdriver/support/wait.py\", line 90, in until\n    raise TimeoutException(message, screen, stacktrace)\nselenium.common.exceptions.TimeoutException: Message: \nStacktrace:\n#0 0x558be34c7463 <unknown>\n#1 0x558be328b8d8 <unknown>\n#2 0x558be32c943a <unknown>\n#3 0x558be32c9651 <unknown>\n#4 0x558be33057a4 <unknown>\n#5 0x558be32ea64d <unknown>\n#6 0x558be330330f <unknown>\n#7 0x558be32ea443 <unknown>\n#8 0x558be32bb3c5 <unknown>\n#9 0x558be32bc531 <unknown>\n#10 0x558be3519dce <unknown>\n#11 0x558be351d192 <unknown>\n#12 0x558be34fe93e <unknown>\n#13 0x558be351e103 <unknown>\n#14 0x558be34f1d85 <unknown>\n#15 0x558be353f0a8 <unknown>\n#16 0x558be353f239 <unknown>\n#17 0x558be355a492 <unknown>\n#18 0x7f7cb393f609 start_thread\n\n\nDuring handling of the above exception, another exception occurred:\n\nTraceback (most recent call last):\n  File \"/home/runner/.local/lib/python3.8/site-packages/behave/model.py\", line 1329, in run\n    match.run(runner.context)\n  File \"/home/runner/.local/lib/python3.8/site-packages/behave/matchers.py\", line 98, in run\n    self.func(context, *args, **kwargs)\n  File \"steps/login_steps.py\", line 26, in step_impl\n    log_out = context.driver.find_element(By.XPATH, log_out_xpath)\n  File \"/home/runner/.local/lib/python3.8/site-packages/selenium/webdriver/remote/webdriver.py\", line 856, in find_element\n    return self.execute(Command.FIND_ELEMENT, {\n  File \"/home/runner/.local/lib/python3.8/site-packages/selenium/webdriver/remote/webdriver.py\", line 429, in execute\n    self.error_handler.check_response(response)\n  File \"/home/runner/.local/lib/python3.8/site-packages/selenium/webdriver/remote/errorhandler.py\", line 243, in check_response\n    raise exception_class(message, screen, stacktrace)\nselenium.common.exceptions.NoSuchElementException: Message: no such element: Unable to locate element: {\"method\":\"xpath\",\"selector\":\"/html/body/div/div[1]/div/nav/ul/li[4]/div/ul/li[6]/a\"}\n  (Session info: headless chrome=107.0.5304.87)\nStacktrace:\n#0 0x558be34c7463 <unknown>\n#1 0x558be328b8d8 <unknown>\n#2 0x558be32c943a <unknown>\n#3 0x558be32c9651 <unknown>\n#4 0x558be33057a4 <unknown>\n#5 0x558be32ea64d <unknown>\n#6 0x558be330330f <unknown>\n#7 0x558be32ea443 <unknown>\n#8 0x558be32bb3c5 <unknown>\n#9 0x558be32bc531 <unknown>\n#10 0x558be3519dce <unknown>\n#11 0x558be351d192 <unknown>\n#12 0x558be34fe93e <unknown>\n#13 0x558be351e103 <unknown>\n#14 0x558be34f1d85 <unknown>\n#15 0x558be353f0a8 <unknown>\n#16 0x558be353f239 <unknown>\n#17 0x558be355a492 <unknown>\n#18 0x7f7cb393f609 start_thread\n\n\nTraceback (of failed substep):\n  File \"/home/runner/.local/lib/python3.8/site-packages/behave/model.py\", line 1329, in run\n    match.run(runner.context)\n  File \"/home/runner/.local/lib/python3.8/site-packages/behave/matchers.py\", line 98, in run\n    self.func(context, *args, **kwargs)\n  File \"steps/login_steps.py\", line 26, in step_impl\n    log_out = context.driver.find_element(By.XPATH, log_out_xpath)\n  File \"/home/runner/.local/lib/python3.8/site-packages/selenium/webdriver/remote/webdriver.py\", line 856, in find_element\n    return self.execute(Command.FIND_ELEMENT, {\n  File \"/home/runner/.local/lib/python3.8/site-packages/selenium/webdriver/remote/webdriver.py\", line 429, in execute\n    self.error_handler.check_response(response)\n  File \"/home/runner/.local/lib/python3.8/site-packages/selenium/webdriver/remote/errorhandler.py\", line 243, in check_response\n    raise exception_class(message, screen, stacktrace)\n\n","time":{"start":1667419956041,"stop":1667419966418,"duration":10377}},{"uid":"621f583d532a8d10","reportUrl":"https://timjden.github.io/cinc_assignment/35//#testresult/621f583d532a8d10","status":"failed","statusDetails":"AssertionError\n","time":{"start":1667418298110,"stop":1667418312424,"duration":14314}},{"uid":"4148ddda5e70cd54","reportUrl":"https://timjden.github.io/cinc_assignment/34//#testresult/4148ddda5e70cd54","status":"failed","statusDetails":"AssertionError\n","time":{"start":1667417982117,"stop":1667417995364,"duration":13247}},{"uid":"b73897d47932e320","reportUrl":"https://timjden.github.io/cinc_assignment/33//#testresult/b73897d47932e320","status":"failed","statusDetails":"AssertionError\n","time":{"start":1667417510841,"stop":1667417523721,"duration":12880}},{"uid":"b6c9c4d2d5de36fe","reportUrl":"https://timjden.github.io/cinc_assignment/32//#testresult/b6c9c4d2d5de36fe","status":"failed","statusDetails":"AssertionError\n","time":{"start":1667414664028,"stop":1667414676944,"duration":12916}},{"uid":"7b881886dc96b54d","reportUrl":"https://timjden.github.io/cinc_assignment/31//#testresult/7b881886dc96b54d","status":"failed","statusDetails":"AssertionError\n","time":{"start":1667414596390,"stop":1667414608984,"duration":12594}},{"uid":"eff9a169f67dd42e","reportUrl":"https://timjden.github.io/cinc_assignment/30//#testresult/eff9a169f67dd42e","status":"failed","statusDetails":"AssertionError\n","time":{"start":1667414335418,"stop":1667414348050,"duration":12632}},{"uid":"a0d603ea795c3327","reportUrl":"https://timjden.github.io/cinc_assignment/29//#testresult/a0d603ea795c3327","status":"failed","statusDetails":"AssertionError: FAILED SUB-STEP: Given User is on the Home page\nSubstep info: Traceback (most recent call last):\n  File \"steps/login_steps.py\", line 18, in step_impl\n    wait_for_element_visibility(context, page_title_xpath)\n  File \"/home/runner/work/cinc_assignment/cinc_assignment/features/utils.py\", line 5, in wait_for_element_visibility\n    context.wait.until(expected_conditions.visibility_of_element_located((By.XPATH, element_xpath)))\n  File \"/home/runner/.local/lib/python3.8/site-packages/selenium/webdriver/support/wait.py\", line 90, in until\n    raise TimeoutException(message, screen, stacktrace)\nselenium.common.exceptions.TimeoutException: Message: \nStacktrace:\n#0 0x55feffd8e2c3 <unknown>\n#1 0x55feffb9783a <unknown>\n#2 0x55feffbd0985 <unknown>\n#3 0x55feffbd0b61 <unknown>\n#4 0x55feffc08d14 <unknown>\n#5 0x55feffbeef6d <unknown>\n#6 0x55feffc06a50 <unknown>\n#7 0x55feffbeed63 <unknown>\n#8 0x55feffbc37e3 <unknown>\n#9 0x55feffbc4a21 <unknown>\n#10 0x55feffddc18e <unknown>\n#11 0x55feffddf622 <unknown>\n#12 0x55feffdc2aae <unknown>\n#13 0x55feffde02a3 <unknown>\n#14 0x55feffdb6ecf <unknown>\n#15 0x55feffe00588 <unknown>\n#16 0x55feffe00706 <unknown>\n#17 0x55feffe1a8b2 <unknown>\n#18 0x7fc3efce6609 <unknown>\n\n\nDuring handling of the above exception, another exception occurred:\n\nTraceback (most recent call last):\n  File \"/home/runner/.local/lib/python3.8/site-packages/behave/model.py\", line 1329, in run\n    match.run(runner.context)\n  File \"/home/runner/.local/lib/python3.8/site-packages/behave/matchers.py\", line 98, in run\n    self.func(context, *args, **kwargs)\n  File \"steps/login_steps.py\", line 27, in step_impl\n    log_out = context.driver.find_element(By.XPATH, log_out_xpath)\n  File \"/home/runner/.local/lib/python3.8/site-packages/selenium/webdriver/remote/webdriver.py\", line 856, in find_element\n    return self.execute(Command.FIND_ELEMENT, {\n  File \"/home/runner/.local/lib/python3.8/site-packages/selenium/webdriver/remote/webdriver.py\", line 429, in execute\n    self.error_handler.check_response(response)\n  File \"/home/runner/.local/lib/python3.8/site-packages/selenium/webdriver/remote/errorhandler.py\", line 243, in check_response\n    raise exception_class(message, screen, stacktrace)\nselenium.common.exceptions.NoSuchElementException: Message: no such element: Unable to locate element: {\"method\":\"xpath\",\"selector\":\"/html/body/div/div[1]/div/nav/ul/li[4]/div/ul/li[6]/a\"}\n  (Session info: headless chrome=106.0.5249.119)\nStacktrace:\n#0 0x55feffd8e2c3 <unknown>\n#1 0x55feffb9783a <unknown>\n#2 0x55feffbd0985 <unknown>\n#3 0x55feffbd0b61 <unknown>\n#4 0x55feffc08d14 <unknown>\n#5 0x55feffbeef6d <unknown>\n#6 0x55feffc06a50 <unknown>\n#7 0x55feffbeed63 <unknown>\n#8 0x55feffbc37e3 <unknown>\n#9 0x55feffbc4a21 <unknown>\n#10 0x55feffddc18e <unknown>\n#11 0x55feffddf622 <unknown>\n#12 0x55feffdc2aae <unknown>\n#13 0x55feffde02a3 <unknown>\n#14 0x55feffdb6ecf <unknown>\n#15 0x55feffe00588 <unknown>\n#16 0x55feffe00706 <unknown>\n#17 0x55feffe1a8b2 <unknown>\n#18 0x7fc3efce6609 <unknown>\n\n\nTraceback (of failed substep):\n  File \"/home/runner/.local/lib/python3.8/site-packages/behave/model.py\", line 1329, in run\n    match.run(runner.context)\n  File \"/home/runner/.local/lib/python3.8/site-packages/behave/matchers.py\", line 98, in run\n    self.func(context, *args, **kwargs)\n  File \"steps/login_steps.py\", line 27, in step_impl\n    log_out = context.driver.find_element(By.XPATH, log_out_xpath)\n  File \"/home/runner/.local/lib/python3.8/site-packages/selenium/webdriver/remote/webdriver.py\", line 856, in find_element\n    return self.execute(Command.FIND_ELEMENT, {\n  File \"/home/runner/.local/lib/python3.8/site-packages/selenium/webdriver/remote/webdriver.py\", line 429, in execute\n    self.error_handler.check_response(response)\n  File \"/home/runner/.local/lib/python3.8/site-packages/selenium/webdriver/remote/errorhandler.py\", line 243, in check_response\n    raise exception_class(message, screen, stacktrace)\n\n","time":{"start":1667414212348,"stop":1667414222731,"duration":10383}},{"uid":"cb8db3b7734f7ee5","reportUrl":"https://timjden.github.io/cinc_assignment/28//#testresult/cb8db3b7734f7ee5","status":"failed","statusDetails":"AssertionError\n","time":{"start":1667414143408,"stop":1667414157357,"duration":13949}},{"uid":"90a326291408e03","reportUrl":"https://timjden.github.io/cinc_assignment/28//#testresult/90a326291408e03","status":"failed","statusDetails":"AssertionError\n","time":{"start":1667414015812,"stop":1667414029204,"duration":13392}},{"uid":"321233665647f3c9","reportUrl":"https://timjden.github.io/cinc_assignment/27//#testresult/321233665647f3c9","status":"failed","statusDetails":"AssertionError\n","time":{"start":1667413857582,"stop":1667413870840,"duration":13258}},{"uid":"66ae1c379c2a0fa0","reportUrl":"https://timjden.github.io/cinc_assignment/26//#testresult/66ae1c379c2a0fa0","status":"failed","statusDetails":"AssertionError\n","time":{"start":1667413672250,"stop":1667413686391,"duration":14141}},{"uid":"357cb1795d771f83","reportUrl":"https://timjden.github.io/cinc_assignment/25//#testresult/357cb1795d771f83","status":"failed","statusDetails":"AssertionError: FAILED SUB-STEP: Given User is on the Home page\nSubstep info: Traceback (most recent call last):\n  File \"steps/login_steps.py\", line 18, in step_impl\n    wait_for_element_visibility(context, page_title_xpath)\n  File \"/home/runner/work/cinc_assignment/cinc_assignment/features/utils.py\", line 5, in wait_for_element_visibility\n    context.wait.until(expected_conditions.visibility_of_element_located((By.XPATH, element_xpath)))\n  File \"/home/runner/.local/lib/python3.8/site-packages/selenium/webdriver/support/wait.py\", line 90, in until\n    raise TimeoutException(message, screen, stacktrace)\nselenium.common.exceptions.TimeoutException: Message: \nStacktrace:\n#0 0x55e01270a2c3 <unknown>\n#1 0x55e01251383a <unknown>\n#2 0x55e01254c985 <unknown>\n#3 0x55e01254cb61 <unknown>\n#4 0x55e012584d14 <unknown>\n#5 0x55e01256af6d <unknown>\n#6 0x55e012582a50 <unknown>\n#7 0x55e01256ad63 <unknown>\n#8 0x55e01253f7e3 <unknown>\n#9 0x55e012540a21 <unknown>\n#10 0x55e01275818e <unknown>\n#11 0x55e01275b622 <unknown>\n#12 0x55e01273eaae <unknown>\n#13 0x55e01275c2a3 <unknown>\n#14 0x55e012732ecf <unknown>\n#15 0x55e01277c588 <unknown>\n#16 0x55e01277c706 <unknown>\n#17 0x55e0127968b2 <unknown>\n#18 0x7f07ef7f3609 <unknown>\n\n\nDuring handling of the above exception, another exception occurred:\n\nTraceback (most recent call last):\n  File \"/home/runner/.local/lib/python3.8/site-packages/behave/model.py\", line 1329, in run\n    match.run(runner.context)\n  File \"/home/runner/.local/lib/python3.8/site-packages/behave/matchers.py\", line 98, in run\n    self.func(context, *args, **kwargs)\n  File \"steps/login_steps.py\", line 27, in step_impl\n    log_out = context.driver.find_element(By.XPATH, log_out_xpath)\n  File \"/home/runner/.local/lib/python3.8/site-packages/selenium/webdriver/remote/webdriver.py\", line 856, in find_element\n    return self.execute(Command.FIND_ELEMENT, {\n  File \"/home/runner/.local/lib/python3.8/site-packages/selenium/webdriver/remote/webdriver.py\", line 429, in execute\n    self.error_handler.check_response(response)\n  File \"/home/runner/.local/lib/python3.8/site-packages/selenium/webdriver/remote/errorhandler.py\", line 243, in check_response\n    raise exception_class(message, screen, stacktrace)\nselenium.common.exceptions.NoSuchElementException: Message: no such element: Unable to locate element: {\"method\":\"xpath\",\"selector\":\"/html/body/div/div[1]/div/nav/ul/li[4]/div/ul/li[6]/a\"}\n  (Session info: headless chrome=106.0.5249.119)\nStacktrace:\n#0 0x55e01270a2c3 <unknown>\n#1 0x55e01251383a <unknown>\n#2 0x55e01254c985 <unknown>\n#3 0x55e01254cb61 <unknown>\n#4 0x55e012584d14 <unknown>\n#5 0x55e01256af6d <unknown>\n#6 0x55e012582a50 <unknown>\n#7 0x55e01256ad63 <unknown>\n#8 0x55e01253f7e3 <unknown>\n#9 0x55e012540a21 <unknown>\n#10 0x55e01275818e <unknown>\n#11 0x55e01275b622 <unknown>\n#12 0x55e01273eaae <unknown>\n#13 0x55e01275c2a3 <unknown>\n#14 0x55e012732ecf <unknown>\n#15 0x55e01277c588 <unknown>\n#16 0x55e01277c706 <unknown>\n#17 0x55e0127968b2 <unknown>\n#18 0x7f07ef7f3609 <unknown>\n\n\nTraceback (of failed substep):\n  File \"/home/runner/.local/lib/python3.8/site-packages/behave/model.py\", line 1329, in run\n    match.run(runner.context)\n  File \"/home/runner/.local/lib/python3.8/site-packages/behave/matchers.py\", line 98, in run\n    self.func(context, *args, **kwargs)\n  File \"steps/login_steps.py\", line 27, in step_impl\n    log_out = context.driver.find_element(By.XPATH, log_out_xpath)\n  File \"/home/runner/.local/lib/python3.8/site-packages/selenium/webdriver/remote/webdriver.py\", line 856, in find_element\n    return self.execute(Command.FIND_ELEMENT, {\n  File \"/home/runner/.local/lib/python3.8/site-packages/selenium/webdriver/remote/webdriver.py\", line 429, in execute\n    self.error_handler.check_response(response)\n  File \"/home/runner/.local/lib/python3.8/site-packages/selenium/webdriver/remote/errorhandler.py\", line 243, in check_response\n    raise exception_class(message, screen, stacktrace)\n\n","time":{"start":1667413430917,"stop":1667413441282,"duration":10365}}]},"tags":[]},"source":"f65160d74254cfe.json","parameterValues":["You already have a collection with that title.","uhqom-duqmum-tepXe7","Test Collection","technical_assignment"]}