{"uid":"eff9a169f67dd42e","name":"User can add a Collection with the same name as a deleted Collection -- @1.1 ","fullName":"Collections: User can add a Collection with the same name as a deleted Collection","historyId":"a34d535ff7756f44d3753d91bfe6b623","time":{"start":1667414335418,"stop":1667414348050,"duration":12632},"status":"failed","statusMessage":"AssertionError\n","statusTrace":"  File \"/home/runner/.local/lib/python3.8/site-packages/behave/model.py\", line 1329, in run\n    match.run(runner.context)\n  File \"/home/runner/.local/lib/python3.8/site-packages/behave/matchers.py\", line 98, in run\n    self.func(context, *args, **kwargs)\n  File \"steps/collection_steps.py\", line 176, in step_impl\n    assert message_element.text != error_message\n","flaky":false,"newFailed":false,"newBroken":false,"newPassed":false,"retriesCount":0,"retriesStatusChange":false,"beforeStages":[],"testStage":{"status":"failed","statusMessage":"AssertionError\n","statusTrace":"  File \"/home/runner/.local/lib/python3.8/site-packages/behave/model.py\", line 1329, in run\n    match.run(runner.context)\n  File \"/home/runner/.local/lib/python3.8/site-packages/behave/matchers.py\", line 98, in run\n    self.func(context, *args, **kwargs)\n  File \"steps/collection_steps.py\", line 176, in step_impl\n    assert message_element.text != error_message\n","steps":[{"name":"Given User is logged in as username: technical_assignment, password: uhqom-duqmum-tepXe7","time":{"start":1667414335418,"stop":1667414346761,"duration":11343},"status":"passed","steps":[],"attachments":[],"parameters":[],"stepsCount":0,"attachmentsCount":0,"shouldDisplayMessage":false,"hasContent":false},{"name":"When User adds a Collection with title: Test Collection","time":{"start":1667414346761,"stop":1667414347507,"duration":746},"status":"passed","steps":[],"attachments":[],"parameters":[],"stepsCount":0,"attachmentsCount":0,"shouldDisplayMessage":false,"hasContent":false},{"name":"Then Error: You already have a collection with that title., does not appear","time":{"start":1667414347507,"stop":1667414348050,"duration":543},"status":"failed","statusMessage":"AssertionError\n","statusTrace":"  File \"/home/runner/.local/lib/python3.8/site-packages/behave/model.py\", line 1329, in run\n    match.run(runner.context)\n  File \"/home/runner/.local/lib/python3.8/site-packages/behave/matchers.py\", line 98, in run\n    self.func(context, *args, **kwargs)\n  File \"steps/collection_steps.py\", line 176, in step_impl\n    assert message_element.text != error_message\n","steps":[],"attachments":[],"parameters":[],"stepsCount":0,"attachmentsCount":0,"shouldDisplayMessage":true,"hasContent":true}],"attachments":[],"parameters":[],"stepsCount":3,"attachmentsCount":0,"shouldDisplayMessage":false,"hasContent":true},"afterStages":[],"labels":[{"name":"severity","value":"normal"},{"name":"feature","value":"Collections"},{"name":"framework","value":"behave"},{"name":"language","value":"cpython3"},{"name":"resultFormat","value":"allure2"}],"parameters":[{"name":"error_message","value":"You already have a collection with that title."},{"name":"password","value":"uhqom-duqmum-tepXe7"},{"name":"title","value":"Test Collection"},{"name":"username","value":"technical_assignment"}],"links":[],"hidden":false,"retry":false,"extra":{"severity":"normal","retries":[],"categories":[{"name":"Product defects","matchedStatuses":[],"flaky":false}],"history":{"statistic":{"failed":9,"broken":0,"skipped":0,"passed":0,"unknown":0,"total":9},"items":[{"uid":"a0d603ea795c3327","reportUrl":"https://timjden.github.io/cinc_assignment/29//#testresult/a0d603ea795c3327","status":"failed","statusDetails":"AssertionError: FAILED SUB-STEP: Given User is on the Home page\nSubstep info: Traceback (most recent call last):\n  File \"steps/login_steps.py\", line 18, in step_impl\n    wait_for_element_visibility(context, page_title_xpath)\n  File \"/home/runner/work/cinc_assignment/cinc_assignment/features/utils.py\", line 5, in wait_for_element_visibility\n    context.wait.until(expected_conditions.visibility_of_element_located((By.XPATH, element_xpath)))\n  File \"/home/runner/.local/lib/python3.8/site-packages/selenium/webdriver/support/wait.py\", line 90, in until\n    raise TimeoutException(message, screen, stacktrace)\nselenium.common.exceptions.TimeoutException: Message: \nStacktrace:\n#0 0x55feffd8e2c3 <unknown>\n#1 0x55feffb9783a <unknown>\n#2 0x55feffbd0985 <unknown>\n#3 0x55feffbd0b61 <unknown>\n#4 0x55feffc08d14 <unknown>\n#5 0x55feffbeef6d <unknown>\n#6 0x55feffc06a50 <unknown>\n#7 0x55feffbeed63 <unknown>\n#8 0x55feffbc37e3 <unknown>\n#9 0x55feffbc4a21 <unknown>\n#10 0x55feffddc18e <unknown>\n#11 0x55feffddf622 <unknown>\n#12 0x55feffdc2aae <unknown>\n#13 0x55feffde02a3 <unknown>\n#14 0x55feffdb6ecf <unknown>\n#15 0x55feffe00588 <unknown>\n#16 0x55feffe00706 <unknown>\n#17 0x55feffe1a8b2 <unknown>\n#18 0x7fc3efce6609 <unknown>\n\n\nDuring handling of the above exception, another exception occurred:\n\nTraceback (most recent call last):\n  File \"/home/runner/.local/lib/python3.8/site-packages/behave/model.py\", line 1329, in run\n    match.run(runner.context)\n  File \"/home/runner/.local/lib/python3.8/site-packages/behave/matchers.py\", line 98, in run\n    self.func(context, *args, **kwargs)\n  File \"steps/login_steps.py\", line 27, in step_impl\n    log_out = context.driver.find_element(By.XPATH, log_out_xpath)\n  File \"/home/runner/.local/lib/python3.8/site-packages/selenium/webdriver/remote/webdriver.py\", line 856, in find_element\n    return self.execute(Command.FIND_ELEMENT, {\n  File \"/home/runner/.local/lib/python3.8/site-packages/selenium/webdriver/remote/webdriver.py\", line 429, in execute\n    self.error_handler.check_response(response)\n  File \"/home/runner/.local/lib/python3.8/site-packages/selenium/webdriver/remote/errorhandler.py\", line 243, in check_response\n    raise exception_class(message, screen, stacktrace)\nselenium.common.exceptions.NoSuchElementException: Message: no such element: Unable to locate element: {\"method\":\"xpath\",\"selector\":\"/html/body/div/div[1]/div/nav/ul/li[4]/div/ul/li[6]/a\"}\n  (Session info: headless chrome=106.0.5249.119)\nStacktrace:\n#0 0x55feffd8e2c3 <unknown>\n#1 0x55feffb9783a <unknown>\n#2 0x55feffbd0985 <unknown>\n#3 0x55feffbd0b61 <unknown>\n#4 0x55feffc08d14 <unknown>\n#5 0x55feffbeef6d <unknown>\n#6 0x55feffc06a50 <unknown>\n#7 0x55feffbeed63 <unknown>\n#8 0x55feffbc37e3 <unknown>\n#9 0x55feffbc4a21 <unknown>\n#10 0x55feffddc18e <unknown>\n#11 0x55feffddf622 <unknown>\n#12 0x55feffdc2aae <unknown>\n#13 0x55feffde02a3 <unknown>\n#14 0x55feffdb6ecf <unknown>\n#15 0x55feffe00588 <unknown>\n#16 0x55feffe00706 <unknown>\n#17 0x55feffe1a8b2 <unknown>\n#18 0x7fc3efce6609 <unknown>\n\n\nTraceback (of failed substep):\n  File \"/home/runner/.local/lib/python3.8/site-packages/behave/model.py\", line 1329, in run\n    match.run(runner.context)\n  File \"/home/runner/.local/lib/python3.8/site-packages/behave/matchers.py\", line 98, in run\n    self.func(context, *args, **kwargs)\n  File \"steps/login_steps.py\", line 27, in step_impl\n    log_out = context.driver.find_element(By.XPATH, log_out_xpath)\n  File \"/home/runner/.local/lib/python3.8/site-packages/selenium/webdriver/remote/webdriver.py\", line 856, in find_element\n    return self.execute(Command.FIND_ELEMENT, {\n  File \"/home/runner/.local/lib/python3.8/site-packages/selenium/webdriver/remote/webdriver.py\", line 429, in execute\n    self.error_handler.check_response(response)\n  File \"/home/runner/.local/lib/python3.8/site-packages/selenium/webdriver/remote/errorhandler.py\", line 243, in check_response\n    raise exception_class(message, screen, stacktrace)\n\n","time":{"start":1667414212348,"stop":1667414222731,"duration":10383}},{"uid":"cb8db3b7734f7ee5","reportUrl":"https://timjden.github.io/cinc_assignment/28//#testresult/cb8db3b7734f7ee5","status":"failed","statusDetails":"AssertionError\n","time":{"start":1667414143408,"stop":1667414157357,"duration":13949}},{"uid":"90a326291408e03","reportUrl":"https://timjden.github.io/cinc_assignment/28//#testresult/90a326291408e03","status":"failed","statusDetails":"AssertionError\n","time":{"start":1667414015812,"stop":1667414029204,"duration":13392}},{"uid":"321233665647f3c9","reportUrl":"https://timjden.github.io/cinc_assignment/27//#testresult/321233665647f3c9","status":"failed","statusDetails":"AssertionError\n","time":{"start":1667413857582,"stop":1667413870840,"duration":13258}},{"uid":"66ae1c379c2a0fa0","reportUrl":"https://timjden.github.io/cinc_assignment/26//#testresult/66ae1c379c2a0fa0","status":"failed","statusDetails":"AssertionError\n","time":{"start":1667413672250,"stop":1667413686391,"duration":14141}},{"uid":"357cb1795d771f83","reportUrl":"https://timjden.github.io/cinc_assignment/25//#testresult/357cb1795d771f83","status":"failed","statusDetails":"AssertionError: FAILED SUB-STEP: Given User is on the Home page\nSubstep info: Traceback (most recent call last):\n  File \"steps/login_steps.py\", line 18, in step_impl\n    wait_for_element_visibility(context, page_title_xpath)\n  File \"/home/runner/work/cinc_assignment/cinc_assignment/features/utils.py\", line 5, in wait_for_element_visibility\n    context.wait.until(expected_conditions.visibility_of_element_located((By.XPATH, element_xpath)))\n  File \"/home/runner/.local/lib/python3.8/site-packages/selenium/webdriver/support/wait.py\", line 90, in until\n    raise TimeoutException(message, screen, stacktrace)\nselenium.common.exceptions.TimeoutException: Message: \nStacktrace:\n#0 0x55e01270a2c3 <unknown>\n#1 0x55e01251383a <unknown>\n#2 0x55e01254c985 <unknown>\n#3 0x55e01254cb61 <unknown>\n#4 0x55e012584d14 <unknown>\n#5 0x55e01256af6d <unknown>\n#6 0x55e012582a50 <unknown>\n#7 0x55e01256ad63 <unknown>\n#8 0x55e01253f7e3 <unknown>\n#9 0x55e012540a21 <unknown>\n#10 0x55e01275818e <unknown>\n#11 0x55e01275b622 <unknown>\n#12 0x55e01273eaae <unknown>\n#13 0x55e01275c2a3 <unknown>\n#14 0x55e012732ecf <unknown>\n#15 0x55e01277c588 <unknown>\n#16 0x55e01277c706 <unknown>\n#17 0x55e0127968b2 <unknown>\n#18 0x7f07ef7f3609 <unknown>\n\n\nDuring handling of the above exception, another exception occurred:\n\nTraceback (most recent call last):\n  File \"/home/runner/.local/lib/python3.8/site-packages/behave/model.py\", line 1329, in run\n    match.run(runner.context)\n  File \"/home/runner/.local/lib/python3.8/site-packages/behave/matchers.py\", line 98, in run\n    self.func(context, *args, **kwargs)\n  File \"steps/login_steps.py\", line 27, in step_impl\n    log_out = context.driver.find_element(By.XPATH, log_out_xpath)\n  File \"/home/runner/.local/lib/python3.8/site-packages/selenium/webdriver/remote/webdriver.py\", line 856, in find_element\n    return self.execute(Command.FIND_ELEMENT, {\n  File \"/home/runner/.local/lib/python3.8/site-packages/selenium/webdriver/remote/webdriver.py\", line 429, in execute\n    self.error_handler.check_response(response)\n  File \"/home/runner/.local/lib/python3.8/site-packages/selenium/webdriver/remote/errorhandler.py\", line 243, in check_response\n    raise exception_class(message, screen, stacktrace)\nselenium.common.exceptions.NoSuchElementException: Message: no such element: Unable to locate element: {\"method\":\"xpath\",\"selector\":\"/html/body/div/div[1]/div/nav/ul/li[4]/div/ul/li[6]/a\"}\n  (Session info: headless chrome=106.0.5249.119)\nStacktrace:\n#0 0x55e01270a2c3 <unknown>\n#1 0x55e01251383a <unknown>\n#2 0x55e01254c985 <unknown>\n#3 0x55e01254cb61 <unknown>\n#4 0x55e012584d14 <unknown>\n#5 0x55e01256af6d <unknown>\n#6 0x55e012582a50 <unknown>\n#7 0x55e01256ad63 <unknown>\n#8 0x55e01253f7e3 <unknown>\n#9 0x55e012540a21 <unknown>\n#10 0x55e01275818e <unknown>\n#11 0x55e01275b622 <unknown>\n#12 0x55e01273eaae <unknown>\n#13 0x55e01275c2a3 <unknown>\n#14 0x55e012732ecf <unknown>\n#15 0x55e01277c588 <unknown>\n#16 0x55e01277c706 <unknown>\n#17 0x55e0127968b2 <unknown>\n#18 0x7f07ef7f3609 <unknown>\n\n\nTraceback (of failed substep):\n  File \"/home/runner/.local/lib/python3.8/site-packages/behave/model.py\", line 1329, in run\n    match.run(runner.context)\n  File \"/home/runner/.local/lib/python3.8/site-packages/behave/matchers.py\", line 98, in run\n    self.func(context, *args, **kwargs)\n  File \"steps/login_steps.py\", line 27, in step_impl\n    log_out = context.driver.find_element(By.XPATH, log_out_xpath)\n  File \"/home/runner/.local/lib/python3.8/site-packages/selenium/webdriver/remote/webdriver.py\", line 856, in find_element\n    return self.execute(Command.FIND_ELEMENT, {\n  File \"/home/runner/.local/lib/python3.8/site-packages/selenium/webdriver/remote/webdriver.py\", line 429, in execute\n    self.error_handler.check_response(response)\n  File \"/home/runner/.local/lib/python3.8/site-packages/selenium/webdriver/remote/errorhandler.py\", line 243, in check_response\n    raise exception_class(message, screen, stacktrace)\n\n","time":{"start":1667413430917,"stop":1667413441282,"duration":10365}},{"uid":"747c1648444e509e","reportUrl":"https://timjden.github.io/cinc_assignment/24//#testresult/747c1648444e509e","status":"failed","statusDetails":"AssertionError\n","time":{"start":1667412789539,"stop":1667412802782,"duration":13243}},{"uid":"d9d6c18078018573","reportUrl":"https://timjden.github.io/cinc_assignment/23//#testresult/d9d6c18078018573","status":"failed","statusDetails":"AssertionError\n","time":{"start":1667412558912,"stop":1667412572022,"duration":13110}}]},"tags":[]},"source":"eff9a169f67dd42e.json","parameterValues":["You already have a collection with that title.","uhqom-duqmum-tepXe7","Test Collection","technical_assignment"]}